Workbook

Sheet 能源消费结构计算公式
A1: 位置 | B1: 公式 (Sheet名!A1 = 公式)
A2: 能源消费结构!C1 | B2: 能源消费结构!C1 = 数据模板!E5
A3: 能源消费结构!D1 | B3: 能源消费结构!D1 = 数据模板!F5
A4: 能源消费结构!E1 | B4: 能源消费结构!E1 = 数据模板!G5
A5: 能源消费结构!F1 | B5: 能源消费结构!F1 = 数据模板!H5
A6: 能源消费结构!G1 | B6: 能源消费结构!G1 = 数据模板!I5
A7: 能源消费结构!H1 | B7: 能源消费结构!H1 = 数据模板!J5
A8: 能源消费结构!I1 | B8: 能源消费结构!I1 = 数据模板!K5
A9: 能源消费结构!J1 | B9: 能源消费结构!J1 = 数据模板!L5
A10: 能源消费结构!K1 | B10: 能源消费结构!K1 = 数据模板!M5
A11: 能源消费结构!AA1 | B11: 能源消费结构!AA1 = '能源消费结构'!C1
A12: 能源消费结构!C2 | B12: 能源消费结构!C2 = 数据模板!E6
... A1028: 能源消费结构!K77 | B1028: 能源消费结构!K77 = '能源消费结构'!K66/'能源消费结构'!K$67

Sheet 能源消费结构
B1: 亿tce | C1: =[1]数据模板!E5 -> 2020 | D1: =[1]数据模板!F5 -> 2025 | E1: =[1]数据模板!G5 -> 2030 | F1: =[1]数据模板!H5 -> 2035 | G1: =[1]数据模板!I5 -> 2040 | H1: =[1]数据模板!J5 -> 2045 | I1: =[1]数据模板!K5 -> 2050 | J1: =[1]数据模板!L5 -> 2055 | K1: =[1]数据模板!M5 -> 2060 | AA1: =C1 -> 2020 | AB1: 2025 | AC1: 2030 | AD1: 2035 | AE1: 2040 | AF1: 2045 | AG1: 2050 | AH1: 2055 | AI1: 2060 | AO1: 2020 | AP1: 2025 | AQ1: 2030 | AR1: 2035 | AS1: 2040 | AT1: 2045 | AU1: 2050 | AV1: 2055 | AW1: 2060 | BC1: 2020 | BD1: 2025 | BE1: 2030 | BF1: 2035 | BG1: 2040 | BH1: 2045 | BI1: 2050 | BJ1: 2055 | BK1: 2060 | BQ1: 2020 | BR1: 2025 | BS1: 2030 | BT1: 2035 | BU1: 2040 | BV1: 2045 | BW1: 2050 | BX1: 2055 | BY1: 2060
A2: 煤炭 | B2: 工业 | Z2: 工业 | AN2: 工业 | BB2: 工业 | BP2: 工业
A3: 石油 | B3: 工业 | Z3: 建筑 | AN3: 建筑 | BB3: 建筑 | BP3: 建筑
A4: 天然气 | B4: 工业 | Z4: 交通 | AN4: 交通 | BB4: 交通 | BP4: 交通
A5: 电力 | B5: 工业 | Z5: =B20 -> 电力 | AN5: 电力 | BB5: 电力 | BP5: 电力
A6: 氢能 | B6: 工业 | Z6: =B28 -> 氢能 | AN6: 氢能 | BB6: 氢能 | BP6: 氢能
A7: 生物质 | B7: 工业 | Z7: =B31 -> 其他 | AN7: 其他 | AY7: =SUM(AO2:AO7)-SUM(AW2:AW7) -> 0 | BB7: 其他 | BP7: 其他
A8: 煤炭 | B8: 建筑
A9: 石油 | B9: 建筑
A10: 天然气 | B10: 建筑
A11: 电力 | B11: 建筑
A12: 氢能 | B12: 建筑
A13: 生物质 | B13: 建筑
A14: 煤炭 | B14: 交通
A15: 石油 | B15: 交通
A16: 天然气 | B16: 交通
A17: 电力 | B17: 交通
A18: 氢能 | B18: 交通
A19: 生物质 | B19: 交通
... A34: 电力 | B34: 其他
A36: 终端消费结构 | B36: 亿tce | C36: 2020 | D36: 2025 | E36: 2030 | F36: 2035 | G36: 2040 | H36: 2045 | I36: 2050 | J36: 2055 | K36: 2060 | M36: 2020 | N36: 2025 | O36: 2030 | P36: 2035 | Q36: 2040 | R36: 2045 | S36: 2050 | T36: 2055 | U36: 2060
B37: 工业总消费
B38: 建筑总消费
B39: 交通总消费
B40: 其他部门消费
B41: 终端总消费
B43: 工业电气化率
B44: 建筑电气化率
B45: 交通电气化率
B46: 氢能总消费
B47: 氢能占比
B48: 终端电气化率
M49: 2020 | N49: 2025 | O49: 2030 | P49: 2035 | Q49: 2040 | R49: 2045 | S49: 2050 | T49: 2055 | U49: 2060
B50: 煤
B51: 油
B52: 气
B53: 生物质
B54: 氢
B55: 电
A57: 一次能源消费结构 | B57: 亿tce | C57: =C1 -> 2020 | D57: =D1 -> 2025 | E57: =E1 -> 2030 | F57: =F1 -> 2035 | G57: =G1 -> 2040 | H57: =H1 -> 2045 | I57: =I1 -> 2050 | J57: =J1 -> 2055 | K57: =K1 -> 2060
...
