Workbook

Sheet 碳排放轨迹计算公式
A1: 位置 | B1: 公式 (Sheet名!A1 = 公式)
A2: 碳排放轨迹!C1 | B2: 碳排放轨迹!C1 = 数据模板!E5
A3: 碳排放轨迹!D1 | B3: 碳排放轨迹!D1 = 数据模板!F5
A4: 碳排放轨迹!E1 | B4: 碳排放轨迹!E1 = 数据模板!G5
A5: 碳排放轨迹!F1 | B5: 碳排放轨迹!F1 = 数据模板!H5
A6: 碳排放轨迹!G1 | B6: 碳排放轨迹!G1 = 数据模板!I5
A7: 碳排放轨迹!H1 | B7: 碳排放轨迹!H1 = 数据模板!J5
A8: 碳排放轨迹!I1 | B8: 碳排放轨迹!I1 = 数据模板!K5
A9: 碳排放轨迹!J1 | B9: 碳排放轨迹!J1 = 数据模板!L5
A10: 碳排放轨迹!K1 | B10: 碳排放轨迹!K1 = 数据模板!M5
A11: 碳排放轨迹!B2 | B11: 碳排放轨迹!B2 = 数据模板!C24
A12: 碳排放轨迹!C2 | B12: 碳排放轨迹!C2 = 数据模板!E24
... A511: 碳排放轨迹!K78 | B511: 碳排放轨迹!K78 = '碳排放轨迹'!K41

Sheet 碳排放轨迹
C1: =[1]数据模板!E5 -> 2020 | D1: =[1]数据模板!F5 -> 2025 | E1: =[1]数据模板!G5 -> 2030 | F1: =[1]数据模板!H5 -> 2035 | G1: =[1]数据模板!I5 -> 2040 | H1: =[1]数据模板!J5 -> 2045 | I1: =[1]数据模板!K5 -> 2050 | J1: =[1]数据模板!L5 -> 2055 | K1: =[1]数据模板!M5 -> 2060
A2: 工业部门 | B2: =[1]数据模板!C24 -> 来自煤炭
B3: =[1]数据模板!C25 -> 来自石油
B4: =[1]数据模板!C26 -> 来自天然气
B5: =[1]数据模板!C27 -> 工业过程CO2
B6: 来自电力
B7: 来自氢能
B8: 工业CCS
A9: 建筑部门 | B9: =[1]数据模板!C48 -> 来自煤炭
B10: =[1]数据模板!C49 -> 来自石油
B11: =[1]数据模板!C50 -> 来自天然气
B12: 来自电力
A13: 交通部门 | B13: =[1]数据模板!C66 -> 来自煤炭
B14: =[1]数据模板!C67 -> 来自石油
B15: =[1]数据模板!C68 -> 来自天然气
B16: 来自电力
A17: 电力部门 | B17: =[1]数据模板!C126 -> 来自煤炭
B18: =[1]数据模板!C127 -> 来自天然气
B19: =[1]数据模板!C129 -> 化石能源CCS
B20: =[1]数据模板!C130 -> 生物质CCS
A21: 总排放（含间接排放） | B21: 工业(含工业过程）
B22: 建筑
B23: 交通
B24: 电力
A25: 总排放 | B25: 工业(含工业过程）
B26: 建筑
B27: 交通
B28: 电力
C29: =C1 -> 2020 | D29: =D1 -> 2025 | E29: =E1 -> 2030 | F29: =F1 -> 2035 | G29: =G1 -> 2040 | H29: =H1 -> 2045 | I29: =I1 -> 2050 | J29: =J1 -> 2055 | K29: =K1 -> 2060
B30: 工业排放
B31: 工业直接排放
B32: 工业CCS
B33: 建筑排放
B34: 交通排放
B35: 电力排放
B36: 电力直接排放
B37: 电力CCS
B38: 其他排放
B39: DACSS
B40: 能源相关CO2
...
